{"data":[{"0":"2279","error_id":"2279","1":"2021-07-01","error_date":"2021-07-01","2":" 05:32:12.1658","error_time":" 05:32:12.1658","3":"Error api\/Rack\/saverackevent: An error occurred while updating the entries. See the inner exception for details.","error_type":"Error api\/Rack\/saverackevent: An error occurred while updating the entries. See the inner exception for details.","4":"System.Data.Entity.Infrastructure.DbUpdateException An error occurred while updating the entries. See the inner exception for details. Void Throw()    ","error_spec":"System.Data.Entity.Infrastructure.DbUpdateException An error occurred while updating the entries. See the inner exception for details. Void Throw()    ","5":"2","error_freq":"2","6":"SAF.EnterpriseSolutions.DataAccess\\UnitOfWork\\EfWorkUnit.cs","error_file":"SAF.EnterpriseSolutions.DataAccess\\UnitOfWork\\EfWorkUnit.cs","7":"37","error_line":"37","8":"System.Data.Entity.Infrastructure.DbUpdateException An error occurred while updating the entries. See the inner exception for details. Void Throw()    at System.Runtime.ExceptionServices.ExceptionDispatchInfo.Throw()\r\n   at System.Runtime.CompilerServices.TaskAwaiter.HandleNonSuccessAndDebuggerNotification(Task task)\r\n   at SAF.EnterpriseSolutions.DataAccess.UnitOfWork.EfWorkUnit`1.<CommitAsync>d__10.MoveNext() in C:\\agent\\_work\\7\\s\\SAF.EnterpriseSolutions.DataAccess\\UnitOfWork\\EfWorkUnit.cs:line 37\r\n--- End of stack trace from previous location where exception was thrown ---\r\n   at System.Runtime.ExceptionServices.ExceptionDispatchInfo.Throw()\r\n   at System.Runtime.CompilerServices.TaskAwaiter.HandleNonSuccessAndDebuggerNotification(Task task)\r\n   at System.Runtime.CompilerServices.TaskAwaiter.GetResult()\r\n   at SAF.EnterpriseSolutions.DataAccess.Repository.RackRepository.<SaveRackEventAsync>d__23.MoveNext() in C:\\agent\\_work\\7\\s\\SAF.EnterpriseSolutions.DataAccess\\Repository\\RackRepository.cs:line 2264\r\n--- End of stack trace from previous location where exception was thrown ---\r\n   at System.Runtime.ExceptionServices.ExceptionDispatchInfo.Throw()\r\n   at System.Runtime.CompilerServices.TaskAwaiter.HandleNonSuccessAndDebuggerNotification(Task task)\r\n   at SAF.EnterpriseSolutions.Web.Services.Controllers.RackController.<SaveRackEvent>d__10.MoveNext() in C:\\agent\\_work\\7\\s\\SAF.EnterpriseSolutions.Web.Services\\Controllers\\RackController.cs:line 176","error_st":"System.Data.Entity.Infrastructure.DbUpdateException An error occurred while updating the entries. See the inner exception for details. Void Throw()    at System.Runtime.ExceptionServices.ExceptionDispatchInfo.Throw()\r\n   at System.Runtime.CompilerServices.TaskAwaiter.HandleNonSuccessAndDebuggerNotification(Task task)\r\n   at SAF.EnterpriseSolutions.DataAccess.UnitOfWork.EfWorkUnit`1.<CommitAsync>d__10.MoveNext() in C:\\agent\\_work\\7\\s\\SAF.EnterpriseSolutions.DataAccess\\UnitOfWork\\EfWorkUnit.cs:line 37\r\n--- End of stack trace from previous location where exception was thrown ---\r\n   at System.Runtime.ExceptionServices.ExceptionDispatchInfo.Throw()\r\n   at System.Runtime.CompilerServices.TaskAwaiter.HandleNonSuccessAndDebuggerNotification(Task task)\r\n   at System.Runtime.CompilerServices.TaskAwaiter.GetResult()\r\n   at SAF.EnterpriseSolutions.DataAccess.Repository.RackRepository.<SaveRackEventAsync>d__23.MoveNext() in C:\\agent\\_work\\7\\s\\SAF.EnterpriseSolutions.DataAccess\\Repository\\RackRepository.cs:line 2264\r\n--- End of stack trace from previous location where exception was thrown ---\r\n   at System.Runtime.ExceptionServices.ExceptionDispatchInfo.Throw()\r\n   at System.Runtime.CompilerServices.TaskAwaiter.HandleNonSuccessAndDebuggerNotification(Task task)\r\n   at SAF.EnterpriseSolutions.Web.Services.Controllers.RackController.<SaveRackEvent>d__10.MoveNext() in C:\\agent\\_work\\7\\s\\SAF.EnterpriseSolutions.Web.Services\\Controllers\\RackController.cs:line 176"},{"0":"2280","error_id":"2280","1":"2021-07-01","error_date":"2021-07-01","2":" 08:03:19.0230","error_time":" 08:03:19.0230","3":"Error accessing GetComplaintDetails list: Object reference not set to an instance of an object.","error_type":"Error accessing GetComplaintDetails list: Object reference not set to an instance of an object.","4":"System.NullReferenceException Object reference not set to an instance of an object. Void MoveNext()    ","error_spec":"System.NullReferenceException Object reference not set to an instance of an object. Void MoveNext()    ","5":"6","error_freq":"6","6":"SAF.EnterpriseSolutions.DataAccess\\Repository\\ComplaintRepository.cs","error_file":"SAF.EnterpriseSolutions.DataAccess\\Repository\\ComplaintRepository.cs","7":"249","error_line":"249","8":"System.NullReferenceException Object reference not set to an instance of an object. Void MoveNext()    at SAF.EnterpriseSolutions.DataAccess.Repository.ComplaintRepository.<GetComplaintDetails>d__6.MoveNext() in C:\\agent\\_work\\7\\s\\SAF.EnterpriseSolutions.DataAccess\\Repository\\ComplaintRepository.cs:line 249}\r\n","error_st":"System.NullReferenceException Object reference not set to an instance of an object. Void MoveNext()    at SAF.EnterpriseSolutions.DataAccess.Repository.ComplaintRepository.<GetComplaintDetails>d__6.MoveNext() in C:\\agent\\_work\\7\\s\\SAF.EnterpriseSolutions.DataAccess\\Repository\\ComplaintRepository.cs:line 249}\r\n"},{"0":"2281","error_id":"2281","1":"2021-07-01","error_date":"2021-07-01","2":" 05:32:12.1658","error_time":" 05:32:12.1658","3":"Error accessing SaveRackEventAsync : An error occurred while updating the entries. See the inner exception for details.","error_type":"Error accessing SaveRackEventAsync : An error occurred while updating the entries. See the inner exception for details.","4":"System.Data.Entity.Infrastructure.DbUpdateException An error occurred while updating the entries. See the inner exception for details. Void Throw()    ","error_spec":"System.Data.Entity.Infrastructure.DbUpdateException An error occurred while updating the entries. See the inner exception for details. Void Throw()    ","5":"1","error_freq":"1","6":"SAF.EnterpriseSolutions.DataAccess\\UnitOfWork\\EfWorkUnit.cs","error_file":"SAF.EnterpriseSolutions.DataAccess\\UnitOfWork\\EfWorkUnit.cs","7":"37","error_line":"37","8":"System.Data.Entity.Infrastructure.DbUpdateException An error occurred while updating the entries. See the inner exception for details. Void Throw()    at System.Runtime.ExceptionServices.ExceptionDispatchInfo.Throw()\r\n   at System.Runtime.CompilerServices.TaskAwaiter.HandleNonSuccessAndDebuggerNotification(Task task)\r\n   at SAF.EnterpriseSolutions.DataAccess.UnitOfWork.EfWorkUnit`1.<CommitAsync>d__10.MoveNext() in C:\\agent\\_work\\7\\s\\SAF.EnterpriseSolutions.DataAccess\\UnitOfWork\\EfWorkUnit.cs:line 37\r\n--- End of stack trace from previous location where exception was thrown ---\r\n   at System.Runtime.ExceptionServices.ExceptionDispatchInfo.Throw()\r\n   at System.Runtime.CompilerServices.TaskAwaiter.HandleNonSuccessAndDebuggerNotification(Task task)\r\n   at System.Runtime.CompilerServices.TaskAwaiter.GetResult()\r\n   at SAF.EnterpriseSolutions.DataAccess.Repository.RackRepository.<SaveRackEventAsync>d__23.MoveNext() in C:\\agent\\_work\\7\\s\\SAF.EnterpriseSolutions.DataAccess\\Repository\\RackRepository.cs:line 2234","error_st":"System.Data.Entity.Infrastructure.DbUpdateException An error occurred while updating the entries. See the inner exception for details. Void Throw()    at System.Runtime.ExceptionServices.ExceptionDispatchInfo.Throw()\r\n   at System.Runtime.CompilerServices.TaskAwaiter.HandleNonSuccessAndDebuggerNotification(Task task)\r\n   at SAF.EnterpriseSolutions.DataAccess.UnitOfWork.EfWorkUnit`1.<CommitAsync>d__10.MoveNext() in C:\\agent\\_work\\7\\s\\SAF.EnterpriseSolutions.DataAccess\\UnitOfWork\\EfWorkUnit.cs:line 37\r\n--- End of stack trace from previous location where exception was thrown ---\r\n   at System.Runtime.ExceptionServices.ExceptionDispatchInfo.Throw()\r\n   at System.Runtime.CompilerServices.TaskAwaiter.HandleNonSuccessAndDebuggerNotification(Task task)\r\n   at System.Runtime.CompilerServices.TaskAwaiter.GetResult()\r\n   at SAF.EnterpriseSolutions.DataAccess.Repository.RackRepository.<SaveRackEventAsync>d__23.MoveNext() in C:\\agent\\_work\\7\\s\\SAF.EnterpriseSolutions.DataAccess\\Repository\\RackRepository.cs:line 2234"},{"0":"2282","error_id":"2282","1":"2021-07-01","error_date":"2021-07-01","2":" 08:33:43.2336","error_time":" 08:33:43.2336","3":"Error executing SaveTrialInvoice : Value cannot be null.\r\nParameter name: key","error_type":"Error executing SaveTrialInvoice : Value cannot be null.\r\nParameter name: key","4":"System.ArgumentNullException Value cannot be null.\r\nParameter name: key Void ThrowArgumentNullException(System.ExceptionArgument)    ","error_spec":"System.ArgumentNullException Value cannot be null.\r\nParameter name: key Void ThrowArgumentNullException(System.ExceptionArgument)    ","5":"2","error_freq":"2","6":"SAF.EnterpriseSolutions.DataAccess\\Repository\\InvoiceRepository.cs","error_file":"SAF.EnterpriseSolutions.DataAccess\\Repository\\InvoiceRepository.cs","7":"5434","error_line":"5434","8":"System.ArgumentNullException Value cannot be null.\r\nParameter name: key Void ThrowArgumentNullException(System.ExceptionArgument)    at System.ThrowHelper.ThrowArgumentNullException(ExceptionArgument argument)\r\n   at System.Collections.Generic.Dictionary`2.Insert(TKey key, TValue value, Boolean add)\r\n   at SAF.EnterpriseSolutions.DataAccess.Repository.InvoiceRepository.<SaveTrialInvoice>d__63.MoveNext() in C:\\agent\\_work\\7\\s\\SAF.EnterpriseSolutions.DataAccess\\Repository\\InvoiceRepository.cs:line 5434}\r\n","error_st":"System.ArgumentNullException Value cannot be null.\r\nParameter name: key Void ThrowArgumentNullException(System.ExceptionArgument)    at System.ThrowHelper.ThrowArgumentNullException(ExceptionArgument argument)\r\n   at System.Collections.Generic.Dictionary`2.Insert(TKey key, TValue value, Boolean add)\r\n   at SAF.EnterpriseSolutions.DataAccess.Repository.InvoiceRepository.<SaveTrialInvoice>d__63.MoveNext() in C:\\agent\\_work\\7\\s\\SAF.EnterpriseSolutions.DataAccess\\Repository\\InvoiceRepository.cs:line 5434}\r\n"},{"0":"2283","error_id":"2283","1":"2021-07-01","error_date":"2021-07-01","2":" 08:33:43.2492","error_time":" 08:33:43.2492","3":"Error api\/savetrialinvoice: Value cannot be null.\r\nParameter name: key","error_type":"Error api\/savetrialinvoice: Value cannot be null.\r\nParameter name: key","4":"System.ArgumentNullException Value cannot be null.\r\nParameter name: key Void ThrowArgumentNullException(System.ExceptionArgument)    ","error_spec":"System.ArgumentNullException Value cannot be null.\r\nParameter name: key Void ThrowArgumentNullException(System.ExceptionArgument)    ","5":"1","error_freq":"1","6":"SAF.EnterpriseSolutions.DataAccess\\Repository\\InvoiceRepository.cs","error_file":"SAF.EnterpriseSolutions.DataAccess\\Repository\\InvoiceRepository.cs","7":"6515","error_line":"6515","8":"System.ArgumentNullException Value cannot be null.\r\nParameter name: key Void ThrowArgumentNullException(System.ExceptionArgument)    at System.ThrowHelper.ThrowArgumentNullException(ExceptionArgument argument)\r\n   at System.Collections.Generic.Dictionary`2.Insert(TKey key, TValue value, Boolean add)\r\n   at SAF.EnterpriseSolutions.DataAccess.Repository.InvoiceRepository.<SaveTrialInvoice>d__63.MoveNext() in C:\\agent\\_work\\7\\s\\SAF.EnterpriseSolutions.DataAccess\\Repository\\InvoiceRepository.cs:line 6515\r\n--- End of stack trace from previous location where exception was thrown ---\r\n   at System.Runtime.ExceptionServices.ExceptionDispatchInfo.Throw()\r\n   at System.Runtime.CompilerServices.TaskAwaiter.HandleNonSuccessAndDebuggerNotification(Task task)\r\n   at SAF.EnterpriseSolutions.Web.Services.Controllers.InvoiceController.<SaveTrialInvoice>d__19.MoveNext() in C:\\agent\\_work\\7\\s\\SAF.EnterpriseSolutions.Web.Services\\Controllers\\InvoiceController.cs:line 502}\r\n","error_st":"System.ArgumentNullException Value cannot be null.\r\nParameter name: key Void ThrowArgumentNullException(System.ExceptionArgument)    at System.ThrowHelper.ThrowArgumentNullException(ExceptionArgument argument)\r\n   at System.Collections.Generic.Dictionary`2.Insert(TKey key, TValue value, Boolean add)\r\n   at SAF.EnterpriseSolutions.DataAccess.Repository.InvoiceRepository.<SaveTrialInvoice>d__63.MoveNext() in C:\\agent\\_work\\7\\s\\SAF.EnterpriseSolutions.DataAccess\\Repository\\InvoiceRepository.cs:line 6515\r\n--- End of stack trace from previous location where exception was thrown ---\r\n   at System.Runtime.ExceptionServices.ExceptionDispatchInfo.Throw()\r\n   at System.Runtime.CompilerServices.TaskAwaiter.HandleNonSuccessAndDebuggerNotification(Task task)\r\n   at SAF.EnterpriseSolutions.Web.Services.Controllers.InvoiceController.<SaveTrialInvoice>d__19.MoveNext() in C:\\agent\\_work\\7\\s\\SAF.EnterpriseSolutions.Web.Services\\Controllers\\InvoiceController.cs:line 502}\r\n"},{"0":"2284","error_id":"2284","1":"2021-07-01","error_date":"2021-07-01","2":" 10:42:42.7592","error_time":" 10:42:42.7592","3":"Error api\/compassIVFiles: Sequence contains no elements","error_type":"Error api\/compassIVFiles: Sequence contains no elements","4":"System.InvalidOperationException Sequence contains no elements TSource First[TSource](System.Collections.Generic.IEnumerable`1[TSource])    ","error_spec":"System.InvalidOperationException Sequence contains no elements TSource First[TSource](System.Collections.Generic.IEnumerable`1[TSource])    ","5":"5","error_freq":"5","6":"SAF.EnterpriseSolutions.DataAccess\\Repository\\ComplexFabQuoteRepository2.cs","error_file":"SAF.EnterpriseSolutions.DataAccess\\Repository\\ComplexFabQuoteRepository2.cs","7":"352","error_line":"352","8":"System.InvalidOperationException Sequence contains no elements TSource First[TSource](System.Collections.Generic.IEnumerable`1[TSource])    at System.Linq.Enumerable.First[TSource](IEnumerable`1 source)\r\n   at SAF.EnterpriseSolutions.DataAccess.Repository.ComplexFabQuoteRepository.<CompassIVFiles>d__1.MoveNext() in C:\\agent\\_work\\7\\s\\SAF.EnterpriseSolutions.DataAccess\\Repository\\ComplexFabQuoteRepository2.cs:line 352\r\n--- End of stack trace from previous location where exception was thrown ---\r\n   at System.Runtime.ExceptionServices.ExceptionDispatchInfo.Throw()\r\n   at System.Runtime.CompilerServices.TaskAwaiter.HandleNonSuccessAndDebuggerNotification(Task task)\r\n   at SAF.EnterpriseSolutions.Web.Services.Controllers.ComplexFabQuoteController.<CompassIVFiles>d__21.MoveNext() in C:\\agent\\_work\\7\\s\\SAF.EnterpriseSolutions.Web.Services\\Controllers\\ComplexFabQuoteController.cs:line 634}\r\n","error_st":"System.InvalidOperationException Sequence contains no elements TSource First[TSource](System.Collections.Generic.IEnumerable`1[TSource])    at System.Linq.Enumerable.First[TSource](IEnumerable`1 source)\r\n   at SAF.EnterpriseSolutions.DataAccess.Repository.ComplexFabQuoteRepository.<CompassIVFiles>d__1.MoveNext() in C:\\agent\\_work\\7\\s\\SAF.EnterpriseSolutions.DataAccess\\Repository\\ComplexFabQuoteRepository2.cs:line 352\r\n--- End of stack trace from previous location where exception was thrown ---\r\n   at System.Runtime.ExceptionServices.ExceptionDispatchInfo.Throw()\r\n   at System.Runtime.CompilerServices.TaskAwaiter.HandleNonSuccessAndDebuggerNotification(Task task)\r\n   at SAF.EnterpriseSolutions.Web.Services.Controllers.ComplexFabQuoteController.<CompassIVFiles>d__21.MoveNext() in C:\\agent\\_work\\7\\s\\SAF.EnterpriseSolutions.Web.Services\\Controllers\\ComplexFabQuoteController.cs:line 634}\r\n"},{"0":"2285","error_id":"2285","1":"2021-07-01","error_date":"2021-07-01","2":" 10:43:04.0334","error_time":" 10:43:04.0334","3":"Error api\/compassIVFiles: The process cannot access the file '247380.bat' because it is being used by another process.","error_type":"Error api\/compassIVFiles: The process cannot access the file '247380.bat' because it is being used by another process.","4":"System.IO.IOException The process cannot access the file '247380.bat' because it is being used by another process. Void MoveNext()    ","error_spec":"System.IO.IOException The process cannot access the file '247380.bat' because it is being used by another process. Void MoveNext()    ","5":"4","error_freq":"4","6":"SAF.EnterpriseSolutions.DataAccess\\Repository\\ComplexFabQuoteRepository2.cs","error_file":"SAF.EnterpriseSolutions.DataAccess\\Repository\\ComplexFabQuoteRepository2.cs","7":"70","error_line":"70","8":"System.IO.IOException The process cannot access the file '247380.bat' because it is being used by another process. Void MoveNext()    at SAF.EnterpriseSolutions.DataAccess.Repository.ComplexFabQuoteRepository.<CompassIVFiles>d__1.MoveNext() in C:\\agent\\_work\\7\\s\\SAF.EnterpriseSolutions.DataAccess\\Repository\\ComplexFabQuoteRepository2.cs:line 70\r\n--- End of stack trace from previous location where exception was thrown ---\r\n   at System.Runtime.ExceptionServices.ExceptionDispatchInfo.Throw()\r\n   at System.Runtime.CompilerServices.TaskAwaiter.HandleNonSuccessAndDebuggerNotification(Task task)\r\n   at SAF.EnterpriseSolutions.Web.Services.Controllers.ComplexFabQuoteController.<CompassIVFiles>d__21.MoveNext() in C:\\agent\\_work\\7\\s\\SAF.EnterpriseSolutions.Web.Services\\Controllers\\ComplexFabQuoteController.cs:line 634}\r\n","error_st":"System.IO.IOException The process cannot access the file '247380.bat' because it is being used by another process. Void MoveNext()    at SAF.EnterpriseSolutions.DataAccess.Repository.ComplexFabQuoteRepository.<CompassIVFiles>d__1.MoveNext() in C:\\agent\\_work\\7\\s\\SAF.EnterpriseSolutions.DataAccess\\Repository\\ComplexFabQuoteRepository2.cs:line 70\r\n--- End of stack trace from previous location where exception was thrown ---\r\n   at System.Runtime.ExceptionServices.ExceptionDispatchInfo.Throw()\r\n   at System.Runtime.CompilerServices.TaskAwaiter.HandleNonSuccessAndDebuggerNotification(Task task)\r\n   at SAF.EnterpriseSolutions.Web.Services.Controllers.ComplexFabQuoteController.<CompassIVFiles>d__21.MoveNext() in C:\\agent\\_work\\7\\s\\SAF.EnterpriseSolutions.Web.Services\\Controllers\\ComplexFabQuoteController.cs:line 634}\r\n"},{"0":"2286","error_id":"2286","1":"2021-07-01","error_date":"2021-07-01","2":" 10:43:15.2092","error_time":" 10:43:15.2092","3":"Error api\/compassIVFiles: Sequence contains no elements","error_type":"Error api\/compassIVFiles: Sequence contains no elements","4":"System.InvalidOperationException Sequence contains no elements TSource First[TSource](System.Collections.Generic.IEnumerable`1[TSource])    ","error_spec":"System.InvalidOperationException Sequence contains no elements TSource First[TSource](System.Collections.Generic.IEnumerable`1[TSource])    ","5":"1","error_freq":"1","6":"SAF.EnterpriseSolutions.DataAccess\\Repository\\ComplexFabQuoteRepository2.cs","error_file":"SAF.EnterpriseSolutions.DataAccess\\Repository\\ComplexFabQuoteRepository2.cs","7":"352","error_line":"352","8":"System.InvalidOperationException Sequence contains no elements TSource First[TSource](System.Collections.Generic.IEnumerable`1[TSource])    at System.Linq.Enumerable.First[TSource](IEnumerable`1 source)\r\n   at SAF.EnterpriseSolutions.DataAccess.Repository.ComplexFabQuoteRepository.<CompassIVFiles>d__1.MoveNext() in C:\\agent\\_work\\7\\s\\SAF.EnterpriseSolutions.DataAccess\\Repository\\ComplexFabQuoteRepository2.cs:line 352\r\n--- End of stack trace from previous location where exception was thrown ---\r\n   at System.Runtime.ExceptionServices.ExceptionDispatchInfo.Throw()\r\n   at System.Runtime.CompilerServices.TaskAwaiter.HandleNonSuccessAndDebuggerNotification(Task task)\r\n   at SAF.EnterpriseSolutions.Web.Services.Controllers.ComplexFabQuoteController.<CompassIVFiles>d__21.MoveNext() in C:\\agent\\_work\\7\\s\\SAF.EnterpriseSolutions.Web.Services\\Controllers\\ComplexFabQuoteController.cs:line 634}\r\n","error_st":"System.InvalidOperationException Sequence contains no elements TSource First[TSource](System.Collections.Generic.IEnumerable`1[TSource])    at System.Linq.Enumerable.First[TSource](IEnumerable`1 source)\r\n   at SAF.EnterpriseSolutions.DataAccess.Repository.ComplexFabQuoteRepository.<CompassIVFiles>d__1.MoveNext() in C:\\agent\\_work\\7\\s\\SAF.EnterpriseSolutions.DataAccess\\Repository\\ComplexFabQuoteRepository2.cs:line 352\r\n--- End of stack trace from previous location where exception was thrown ---\r\n   at System.Runtime.ExceptionServices.ExceptionDispatchInfo.Throw()\r\n   at System.Runtime.CompilerServices.TaskAwaiter.HandleNonSuccessAndDebuggerNotification(Task task)\r\n   at SAF.EnterpriseSolutions.Web.Services.Controllers.ComplexFabQuoteController.<CompassIVFiles>d__21.MoveNext() in C:\\agent\\_work\\7\\s\\SAF.EnterpriseSolutions.Web.Services\\Controllers\\ComplexFabQuoteController.cs:line 634}\r\n"},{"0":"2287","error_id":"2287","1":"2021-07-01","error_date":"2021-07-01","2":" 10:43:33.5949","error_time":" 10:43:33.5949","3":"Error api\/compassIVFiles: The process cannot access the file '247380.bat' because it is being used by another process.","error_type":"Error api\/compassIVFiles: The process cannot access the file '247380.bat' because it is being used by another process.","4":"System.IO.IOException The process cannot access the file '247380.bat' because it is being used by another process. Void MoveNext()    ","error_spec":"System.IO.IOException The process cannot access the file '247380.bat' because it is being used by another process. Void MoveNext()    ","5":"1","error_freq":"1","6":"SAF.EnterpriseSolutions.DataAccess\\Repository\\ComplexFabQuoteRepository2.cs","error_file":"SAF.EnterpriseSolutions.DataAccess\\Repository\\ComplexFabQuoteRepository2.cs","7":"70","error_line":"70","8":"System.IO.IOException The process cannot access the file '247380.bat' because it is being used by another process. Void MoveNext()    at SAF.EnterpriseSolutions.DataAccess.Repository.ComplexFabQuoteRepository.<CompassIVFiles>d__1.MoveNext() in C:\\agent\\_work\\7\\s\\SAF.EnterpriseSolutions.DataAccess\\Repository\\ComplexFabQuoteRepository2.cs:line 70\r\n--- End of stack trace from previous location where exception was thrown ---\r\n   at System.Runtime.ExceptionServices.ExceptionDispatchInfo.Throw()\r\n   at System.Runtime.CompilerServices.TaskAwaiter.HandleNonSuccessAndDebuggerNotification(Task task)\r\n   at SAF.EnterpriseSolutions.Web.Services.Controllers.ComplexFabQuoteController.<CompassIVFiles>d__21.MoveNext() in C:\\agent\\_work\\7\\s\\SAF.EnterpriseSolutions.Web.Services\\Controllers\\ComplexFabQuoteController.cs:line 634}\r\n","error_st":"System.IO.IOException The process cannot access the file '247380.bat' because it is being used by another process. Void MoveNext()    at SAF.EnterpriseSolutions.DataAccess.Repository.ComplexFabQuoteRepository.<CompassIVFiles>d__1.MoveNext() in C:\\agent\\_work\\7\\s\\SAF.EnterpriseSolutions.DataAccess\\Repository\\ComplexFabQuoteRepository2.cs:line 70\r\n--- End of stack trace from previous location where exception was thrown ---\r\n   at System.Runtime.ExceptionServices.ExceptionDispatchInfo.Throw()\r\n   at System.Runtime.CompilerServices.TaskAwaiter.HandleNonSuccessAndDebuggerNotification(Task task)\r\n   at SAF.EnterpriseSolutions.Web.Services.Controllers.ComplexFabQuoteController.<CompassIVFiles>d__21.MoveNext() in C:\\agent\\_work\\7\\s\\SAF.EnterpriseSolutions.Web.Services\\Controllers\\ComplexFabQuoteController.cs:line 634}\r\n"},{"0":"2288","error_id":"2288","1":"2021-07-01","error_date":"2021-07-01","2":" 10:43:38.9281","error_time":" 10:43:38.9281","3":"Error api\/compassIVFiles: The process cannot access the file '247380.bat' because it is being used by another process.","error_type":"Error api\/compassIVFiles: The process cannot access the file '247380.bat' because it is being used by another process.","4":"System.IO.IOException The process cannot access the file '247380.bat' because it is being used by another process. Void MoveNext()    ","error_spec":"System.IO.IOException The process cannot access the file '247380.bat' because it is being used by another process. Void MoveNext()    ","5":"1","error_freq":"1","6":"SAF.EnterpriseSolutions.DataAccess\\Repository\\ComplexFabQuoteRepository2.cs","error_file":"SAF.EnterpriseSolutions.DataAccess\\Repository\\ComplexFabQuoteRepository2.cs","7":"70","error_line":"70","8":"System.IO.IOException The process cannot access the file '247380.bat' because it is being used by another process. Void MoveNext()    at SAF.EnterpriseSolutions.DataAccess.Repository.ComplexFabQuoteRepository.<CompassIVFiles>d__1.MoveNext() in C:\\agent\\_work\\7\\s\\SAF.EnterpriseSolutions.DataAccess\\Repository\\ComplexFabQuoteRepository2.cs:line 70\r\n--- End of stack trace from previous location where exception was thrown ---\r\n   at System.Runtime.ExceptionServices.ExceptionDispatchInfo.Throw()\r\n   at System.Runtime.CompilerServices.TaskAwaiter.HandleNonSuccessAndDebuggerNotification(Task task)\r\n   at SAF.EnterpriseSolutions.Web.Services.Controllers.ComplexFabQuoteController.<CompassIVFiles>d__21.MoveNext() in C:\\agent\\_work\\7\\s\\SAF.EnterpriseSolutions.Web.Services\\Controllers\\ComplexFabQuoteController.cs:line 634}\r\n","error_st":"System.IO.IOException The process cannot access the file '247380.bat' because it is being used by another process. Void MoveNext()    at SAF.EnterpriseSolutions.DataAccess.Repository.ComplexFabQuoteRepository.<CompassIVFiles>d__1.MoveNext() in C:\\agent\\_work\\7\\s\\SAF.EnterpriseSolutions.DataAccess\\Repository\\ComplexFabQuoteRepository2.cs:line 70\r\n--- End of stack trace from previous location where exception was thrown ---\r\n   at System.Runtime.ExceptionServices.ExceptionDispatchInfo.Throw()\r\n   at System.Runtime.CompilerServices.TaskAwaiter.HandleNonSuccessAndDebuggerNotification(Task task)\r\n   at SAF.EnterpriseSolutions.Web.Services.Controllers.ComplexFabQuoteController.<CompassIVFiles>d__21.MoveNext() in C:\\agent\\_work\\7\\s\\SAF.EnterpriseSolutions.Web.Services\\Controllers\\ComplexFabQuoteController.cs:line 634}\r\n"},{"0":"2289","error_id":"2289","1":"2021-07-01","error_date":"2021-07-01","2":" 12:29:52.3391","error_time":" 12:29:52.3391","3":"Error ModifyWorkFlowAsync : Invalid shop order number.","error_type":"Error ModifyWorkFlowAsync : Invalid shop order number.","4":"System.Exception Invalid shop order number. Void MoveNext()    ","error_spec":"System.Exception Invalid shop order number. Void MoveNext()    ","5":"1","error_freq":"1","6":"SAF.EnterpriseSolutions.DataAccess\\Repository\\InvOrderRepository.cs","error_file":"SAF.EnterpriseSolutions.DataAccess\\Repository\\InvOrderRepository.cs","7":"819","error_line":"819","8":"System.Exception Invalid shop order number. Void MoveNext()    at SAF.EnterpriseSolutions.DataAccess.Repository.InvOrderRepository.<ModifyWorkFlowAsync>d__7.MoveNext() in C:\\agent\\_work\\7\\s\\SAF.EnterpriseSolutions.DataAccess\\Repository\\InvOrderRepository.cs:line 819}\r\n","error_st":"System.Exception Invalid shop order number. Void MoveNext()    at SAF.EnterpriseSolutions.DataAccess.Repository.InvOrderRepository.<ModifyWorkFlowAsync>d__7.MoveNext() in C:\\agent\\_work\\7\\s\\SAF.EnterpriseSolutions.DataAccess\\Repository\\InvOrderRepository.cs:line 819}\r\n"}]}